<?xml version="1.0"?>
<!-- =================================================================================== -->
<!-- |    TurtleBot3 Burger with OAK-D Pro Camera              | -->
<!-- =================================================================================== -->
<robot name="turtlebot3_burger">

  <!-- Material Definitions -->
  <material name="black">
    <color rgba="0.0 0.0 0.0 1.0" />
  </material>
  <material name="dark">
    <color rgba="0.3 0.3 0.3 1.0" />
  </material>
  <material name="light_black">
    <color rgba="0.4 0.4 0.4 1.0" />
  </material>
  <material name="blue">
    <color rgba="0.0 0.0 0.8 1.0" />
  </material>
  <material name="green">
    <color rgba="0.0 0.8 0.0 1.0" />
  </material>
  <material name="grey">
    <color rgba="0.5 0.5 0.5 1.0" />
  </material>
  <material name="orange">
    <color rgba="1.0 0.4235 0.0392 1.0" />
  </material>
  <material name="brown">
    <color rgba="0.8706 0.8118 0.7647 1.0" />
  </material>
  <material name="red">
    <color rgba="0.8 0.0 0.0 1.0" />
  </material>
  <material name="white">
    <color rgba="1.0 1.0 1.0 1.0" />
  </material>

  <!-- Base Footprint -->
  <link name="base_footprint" />

  <joint name="base_joint" type="fixed">
    <parent link="base_footprint" />
    <child link="base_link" />
    <origin rpy="0 0 0" xyz="0.0 0.0 0.010" />
  </joint>

  <!-- Base Link -->
  <link name="base_link">
    <visual>
      <origin rpy="0 0 0" xyz="-0.032 0 0.0" />
      <geometry>
        <mesh filename="package://turtlebot3_descriptions/meshes/bases/burger_base.stl"
          scale="0.001 0.001 0.001" />
      </geometry>
      <material name="light_black" />
    </visual>
    <collision>
      <origin rpy="0 0 0" xyz="-0.032 0 0.070" />
      <geometry>
        <box size="0.140 0.140 0.143" />
      </geometry>
    </collision>
    <inertial>
      <origin rpy="0 0 0" xyz="-0.033 0 0.07" />
      <mass value="8.2573504e-01" />
      <inertia ixx="2.2124416e-03" ixy="0.0" ixz="0.0" iyy="2.1193702e-03" iyz="0.0"
        izz="2.0064271e-03" />
    </inertial>
  </link>

  <gazebo reference="base_link">
    <material>Gazebo/DarkGrey</material>
  </gazebo>

  <!-- Left Wheel -->
  <joint name="wheel_left_joint" type="continuous">
    <parent link="base_link" />
    <child link="wheel_left_link" />
    <origin rpy="-1.57 0 0" xyz="0.0 0.08 0.023" />
    <axis xyz="0 0 1" />
  </joint>

  <link name="wheel_left_link">
    <visual>
      <origin rpy="1.57 0 0" xyz="0 0 0" />
      <geometry>
        <mesh filename="package://turtlebot3_descriptions/meshes/wheels/left_tire.stl"
          scale="0.001 0.001 0.001" />
      </geometry>
      <material name="dark" />
    </visual>
    <collision>
      <origin rpy="0 0 0" xyz="0 0 0" />
      <geometry>
        <cylinder length="0.018" radius="0.033" />
      </geometry>
    </collision>
    <inertial>
      <origin xyz="0 0 0" />
      <mass value="2.8498940e-02" />
      <inertia ixx="1.1175580e-05" ixy="0.0" ixz="0.0" iyy="1.1192413e-05" iyz="0.0"
        izz="2.0712558e-05" />
    </inertial>
  </link>

  <gazebo reference="wheel_left_link">
    <material>Gazebo/DarkGrey</material>
    <mu1>100000.0</mu1>
    <mu2>100000.0</mu2>
    <kp>1e+5</kp>
    <kd>1</kd>
    <minDepth>0.001</minDepth>
    <maxVel>0.01</maxVel>
  </gazebo>

  <!-- Right Wheel -->
  <joint name="wheel_right_joint" type="continuous">
    <parent link="base_link" />
    <child link="wheel_right_link" />
    <origin rpy="-1.57 0 0" xyz="0.0 -0.080 0.023" />
    <axis xyz="0 0 1" />
  </joint>

  <link name="wheel_right_link">
    <visual>
      <origin rpy="1.57 0 0" xyz="0 0 0" />
      <geometry>
        <mesh filename="package://turtlebot3_descriptions/meshes/wheels/right_tire.stl"
          scale="0.001 0.001 0.001" />
      </geometry>
      <material name="dark" />
    </visual>
    <collision>
      <origin rpy="0 0 0" xyz="0 0 0" />
      <geometry>
        <cylinder length="0.018" radius="0.033" />
      </geometry>
    </collision>
    <inertial>
      <origin xyz="0 0 0" />
      <mass value="2.8498940e-02" />
      <inertia ixx="1.1175580e-05" ixy="0.0" ixz="0.0" iyy="1.1192413e-05" iyz="0.0"
        izz="2.0712558e-05" />
    </inertial>
  </link>

  <gazebo reference="wheel_right_link">
    <material>Gazebo/DarkGrey</material>
    <mu1>100000.0</mu1>
    <mu2>100000.0</mu2>
    <kp>1e+5</kp>
    <kd>1</kd>
    <minDepth>0.001</minDepth>
    <maxVel>0.01</maxVel>
  </gazebo>

  <!-- Caster Wheel -->
  <joint name="caster_back_joint" type="fixed">
    <parent link="base_link" />
    <child link="caster_back_link" />
    <origin rpy="-1.57 0 0" xyz="-0.081 0 -0.004" />
  </joint>

  <link name="caster_back_link">
    <collision>
      <origin rpy="0 0 0" xyz="0 0.001 0" />
      <geometry>
        <box size="0.030 0.009 0.020" />
      </geometry>
    </collision>
    <inertial>
      <origin xyz="0 0 0" />
      <mass value="0.005" />
      <inertia ixx="1.0e-07" ixy="0.0" ixz="0.0" iyy="1.0e-07" iyz="0.0" izz="1.0e-07" />
    </inertial>
  </link>

  <gazebo reference="caster_back_link">
    <mu1>0.0</mu1>
    <mu2>0.0</mu2>
    <kp>1e+5</kp>
    <kd>1</kd>
    <minDepth>0.001</minDepth>
    <maxVel>0.01</maxVel>
  </gazebo>

  <!-- IMU -->
  <joint name="imu_joint" type="fixed">
    <parent link="base_link" />
    <child link="imu_link" />
    <origin rpy="0 0 0" xyz="-0.032 0 0.068" />
  </joint>

  <link name="imu_link" />

  <gazebo reference="imu_link">
      <sensor name="tb3_imu" type="imu">
        <always_on>true</always_on>
        <update_rate>200</update_rate>
        <topic>imu</topic>
        <imu>
          <angular_velocity>
            <x>
              <noise type="gaussian">
                <mean>0.0</mean>
                <stddev>2e-4</stddev>
              </noise>
            </x>
            <y>
              <noise type="gaussian">
                <mean>0.0</mean>
                <stddev>2e-4</stddev>
              </noise>
            </y>
            <z>
              <noise type="gaussian">
                <mean>0.0</mean>
                <stddev>2e-4</stddev>
              </noise>
            </z>
          </angular_velocity>
          <linear_acceleration>
            <x>
              <noise type="gaussian">
                <mean>0.0</mean>
                <stddev>1.7e-2</stddev>
              </noise>
            </x>
            <y>
              <noise type="gaussian">
                <mean>0.0</mean>
                <stddev>1.7e-2</stddev>
              </noise>
            </y>
            <z>
              <noise type="gaussian">
                <mean>0.0</mean>
                <stddev>1.7e-2</stddev>
              </noise>
            </z>
          </linear_acceleration>
        </imu>
      </sensor>
  </gazebo>

  <!-- LiDAR -->
  <joint name="scan_joint" type="fixed">
    <parent link="base_link" />
    <child link="base_scan" />
    <origin rpy="0 0 0" xyz="-0.032 0 0.172" />
  </joint>

  <link name="base_scan">
    <visual>
      <origin rpy="0 0 0" xyz="0 0 0.0" />
      <geometry>
        <mesh filename="package://turtlebot3_descriptions/meshes/sensors/lds.stl"
          scale="0.001 0.001 0.001" />
      </geometry>
      <material name="dark" />
    </visual>
    <collision>
      <origin rpy="0 0 0" xyz="0.015 0 -0.0065" />
      <geometry>
        <cylinder length="0.0315" radius="0.055" />
      </geometry>
    </collision>
    <inertial>
      <mass value="0.114" />
      <origin xyz="0 0 -0.01" />
      <inertia ixx="47.43e-06" ixy="0.0" ixz="0.0" iyy="79.51e-06" iyz="0.0" izz="102.75e-06" />
    </inertial>
  </link>

  <gazebo reference="base_scan">
    <material>Gazebo/DarkGrey</material>
    <sensor name="hls_lfcd_lds" type="gpu_lidar">
      <always_on>true</always_on>
      <visualize>true</visualize>
      <pose>-0.032 0 0.171 0 0 0</pose>
      <update_rate>5</update_rate>
      <topic>scan</topic>
      <gz_frame_id>base_scan</gz_frame_id>
      <lidar>
        <scan>
          <horizontal>
            <samples>360</samples>
            <resolution>1.000000</resolution>
            <min_angle>0.000000</min_angle>
            <max_angle>6.280000</max_angle>
          </horizontal>
        </scan>
        <range>
          <min>0.120000</min>
          <max>3.5</max>
          <resolution>0.015000</resolution>
        </range>
        <noise>
          <type>gaussian</type>
          <mean>0.0</mean>
          <stddev>0.01</stddev>
        </noise>
      </lidar>
    </sensor>
  </gazebo>

  <!-- OAK-D Pro Camera -->
  <link name="oak_d_pro_camera">
    <visual name="meshes">
      <origin xyz="0.0 0.0 0.0" rpy="-0.785 0 0" />
      <geometry>
        <mesh filename="package://turtlebot3_descriptions/meshes/sensors/OAK-D-PRO.stl"
          scale="1.0 1.0 1.0" />
      </geometry>
      <material name="dark" />
    </visual>
    <inertial>
      <origin xyz="0.00099391 -0.00585275 -0.01028175" />
      <mass value="0.09100000" />
      <inertia ixx="0.00000975" ixy="0.0" ixz="0.0" iyy="0.00007087" iyz="0.0" izz="0.00007312" />
    </inertial>
    <collision>
      <origin rpy="-0.785 0.0 0.0" xyz="0 -0.009 -0.004" />
      <geometry>
        <box size="0.1 0.03 0.02" />
      </geometry>
    </collision>
  </link>

  <joint name="joint_oak_d_pro_camera" type="fixed">
    <parent link="base_link" />
    <child link="oak_d_pro_camera" />
    <origin xyz="0.065 0.0 0.11" rpy="1.57 0.0 1.57" />
  </joint>

  <gazebo reference="oak_d_pro_camera">
    <material>Gazebo/DarkGrey</material>
  </gazebo>

  <!-- OAK-D Pro Color Optical Frame -->
  <link name="oak_d_pro_color_optical_frame" />

  <joint name="joint_oak_d_pro_color_optical_frame" type="fixed">
    <parent link="oak_d_pro_camera" />
    <child link="oak_d_pro_color_optical_frame" />
    <origin xyz="0.0 0.0 0.0" rpy="-1.5708 0.0 -1.5708" />
  </joint>

  <!-- RGB Camera Sensor -->
  <gazebo reference="oak_d_pro_color_optical_frame">
    <sensor name="oak_d_pro_rgb_camera" type="camera">
      <always_on>true</always_on>
      <visualize>true</visualize>
      <update_rate>30</update_rate>
      <camera name="oak_d_pro_rgb">
        <horizontal_fov>1.047</horizontal_fov>
        <image>
          <width>640</width>
          <height>480</height>
          <format>R8G8B8</format>
        </image>
        <clip>
          <near>0.1</near>
          <far>100</far>
        </clip>
        <noise>
          <type>gaussian</type>
          <mean>0.0</mean>
          <stddev>0.007</stddev>
        </noise>
      </camera>
      <!--<plugin name="camera_controller" filename="libgazebo_ros_camera.so">
        <ros>
          <namespace>/oak_d_pro</namespace>
          <remapping>image_raw:=rgb/image_raw</remapping>
          <remapping>camera_info:=rgb/camera_info</remapping>
        </ros>
        <camera_name>rgb_camera</camera_name>
        <frame_name>oak_d_pro_color_optical_frame</frame_name>
        <hack_baseline>0.07</hack_baseline>
      </plugin>-->
    </sensor>
  </gazebo>

  <!-- OAK-D Pro Depth Optical Frame -->
  <link name="oak_d_pro_depth_optical_frame" />

  <joint name="joint_oak_d_pro_depth_optical_frame" type="fixed">
    <parent link="oak_d_pro_camera" />
    <child link="oak_d_pro_depth_optical_frame" />
    <origin xyz="0.0 0.0 0.0" rpy="-1.5708 0.0 -1.5708" />
  </joint>

  <!-- Depth Camera Sensor -->
  <gazebo reference="oak_d_pro_depth_optical_frame">
    <sensor name="oak_d_pro_depth_camera" type="depth">
      <always_on>true</always_on>
      <visualize>true</visualize>
      <update_rate>30</update_rate>
      <camera name="oak_d_pro_depth">
        <horizontal_fov>1.047</horizontal_fov>
        <image>
          <width>640</width>
          <height>480</height>
          <format>R_FLOAT32</format>
        </image>
        <clip>
          <near>0.1</near>
          <far>100.0</far>
        </clip>
        <noise>
          <type>gaussian</type>
          <mean>0.0</mean>
          <stddev>0.01</stddev>
        </noise>
      </camera>
      <!--<plugin name="depth_camera_controller" filename="libgazebo_ros_camera.so">
        <ros>
          <namespace>/oak_d_pro</namespace>
          <remapping>depth/image_raw:=depth/image_raw</remapping>
          <remapping>depth/camera_info:=depth/camera_info</remapping>
          <remapping>points:=depth/points</remapping>
        </ros>
        <camera_name>depth_camera</camera_name>
        <frame_name>oak_d_pro_depth_optical_frame</frame_name>
        <hack_baseline>0.07</hack_baseline>
        <min_depth>0.1</min_depth>
        <max_depth>100.0</max_depth>
      </plugin>-->
    </sensor>
  </gazebo>

  <!-- Differential Drive Plugin -->
  <gazebo>
    <plugin filename="gz-sim-diff-drive-system" name="gz::sim::systems::DiffDrive">
      <!-- wheels -->
      <left_joint>wheel_left_joint</left_joint>
      <right_joint>wheel_right_joint</right_joint>

      <!-- kinematics -->
      <wheel_separation>0.160</wheel_separation>
      <wheel_radius>0.033</wheel_radius>

      <!-- limits -->
      <max_linear_acceleration>1.0</max_linear_acceleration>

      <topic>cmd_vel</topic>
      <odom_topic>odom</odom_topic>
      <frame_id>odom</frame_id>
      <tf_topic>/tf</tf_topic>
      <odom_publisher_frequency>30</odom_publisher_frequency>
      <child_frame_id>base_footprint</child_frame_id>
    </plugin>
  </gazebo>

  <!-- Joint State Publisher Plugin -->
  <gazebo>
    <plugin filename="gz-sim-joint-state-publisher-system" name="gz::sim::systems::JointStatePublisher">
      <topic>joint_states</topic>
      <!-- <update_rate>30</update_rate> -->
      <joint_name>wheel_left_joint</joint_name>
      <joint_name>wheel_right_joint</joint_name>
    </plugin>
  </gazebo>

</robot>